<?xml version="1.0"?>
<robot name="incorrect_xacro" xmlns:xacro="http://www.ros.org/wiki/xacro">
  <material name="red">
    <color rgba="1.0 0.0 0.0 1.0"/>
  </material>
  <material name="green">
    <color rgba="0.0 1.0 0.0 1.0"/>
  </material>
  <material name="blue">
    <color rgba="0.0 0.0 1.0 1.0"/>
  </material>
  <material name="yellow">
    <color rgba="1.0 1.0 0.0 1.0"/>
  </material>

  <xacro:macro name="box_inertial" params="mass origin d w h">
    <inertial>
      <origin xyz="${origin}" rpy="0 0 0"/>
      <mass value="${mass}"/>
      <inertia ixx="${mass * (w ** 2 + h ** 2) / 12}"
               ixy="0.0" iyy="${mass * (d ** 2 + h ** 2) / 12}"
               ixz="0.0" iyz="0.0" izz="${mass * (w ** 2 + d ** 2) / 12}"/> 
    </inertial>
  </xacro:macro>
  

  <link name="right_pad1">
    <visual>
      <origin xyz="0.5 0 0.25" rpy="0 0 0"/>
      <geometry>
        <box size="1.0 1.0 0.5" />
      </geometry>
      <material name="red"/>
    </visual>
    <collision>
      <origin xyz="0.5 0 0.25" rpy="0 0 0"/>
      <geometry>
        <box size="1.0 1.0 0.5" />
      </geometry>
    </collision>
    <xacro:box_inertial mass="0.5" origin="0.5 0 0.25" d="1.0" w="1.0" h="0.5"/>
  </link>
  <gazebo reference="right_pad1">
    <material>Gazebo/Red</material>
    <mu1>100000</mu1>
    <mu2>100000</mu2>
    <kp>40000.0</kp>
    <kd>0.0</kd>
    <minDepth>0.0</minDepth>
    <maxContacts>5</maxContacts>
    <selfCollide>false</selfCollide>
    <dampingFactor>0.0</dampingFactor>
  </gazebo>

  <!-- Joints are respect the PARENT in XACRO/URDF -->
  <!-- Joints are respect the CHILD in SDF -->
  <joint name="right_pad1_joint" type="revolute">
    <parent link="right_pad1"/>
    <child  link="right_pad2"/>
    <origin xyz="1.0 0 0.5" rpy="0 -1.57 0"/>
    <axis xyz="0 1 0"/>
    <limit effort="1000.0" lower="-3.14" upper="3.14" velocity="1000.0"/>
    <dynamics damping="0" friction="0"/>
  </joint>

  <link name="right_pad2">
    <collision name="right_pad2_collision">
      <origin xyz="0.5 0 -0.05" rpy="0 0 0"/>
      <geometry>
        <box size="1.0 1.0 0.1" />
      </geometry>
    </collision>
    <visual name="right_pad2_visual">
      <origin xyz="0.5 0 -0.05" rpy="0 0 0"/>
      <geometry>
        <box size="1.0 1.0 0.1" />
      </geometry>
      <material name="green"/>
    </visual>
    <xacro:box_inertial mass="0.5" origin="0.5 0 -0.05" d="1.0" w="1.0" h="0.1"/>
  </link>
  <gazebo reference="right_pad2">
    <material>Gazebo/Green</material>
    <mu1>100000</mu1>
    <mu2>100000</mu2>
    <kp>40000.0</kp>
    <kd>0.0</kd>
    <minDepth>0.0</minDepth>
    <maxContacts>5</maxContacts>
    <selfCollide>false</selfCollide>
    <dampingFactor>0.0</dampingFactor>
  </gazebo>

  <joint name="right_pad2_joint" type="revolute">
    <parent link="right_pad2"/>
    <child  link="right_pad3"/>
    <origin xyz="1.0 0 0" rpy="0 -1.57 0"/>
    <axis xyz="0 1 0"/>
    <limit effort="1000.0" lower="-3.14" upper="3.14" velocity="1000.0"/>
    <dynamics damping="0" friction="0"/>
  </joint>

  <link name="right_pad3">
    <collision name="right_pad3_collision">
      <origin xyz="0.5 0 -0.05" rpy="0 0 0"/>
      <geometry>
        <box size="1.0 1.0 0.1" />
      </geometry>
    </collision>
    <visual name="right_pad3_visual">
      <origin xyz="0.5 0 -0.05" rpy="0 0 0"/>
      <geometry>
        <box size="1.0 1.0 0.1" />
      </geometry>
      <material name="blue"/>
    </visual>
    <xacro:box_inertial mass="0.5" origin="0.5 0 -0.05" d="1.0" w="1.0" h="0.1"/>
  </link>
  <gazebo reference="right_pad3">
    <material>Gazebo/Blue</material>
    <mu1>100000</mu1>
    <mu2>100000</mu2>
    <kp>40000.0</kp>
    <kd>0.0</kd>
    <minDepth>0.0</minDepth>
    <maxContacts>5</maxContacts>
    <selfCollide>false</selfCollide>
    <dampingFactor>0.0</dampingFactor>
  </gazebo>

  <joint name="right_pad3_joint" type="revolute">
    <parent link="right_pad3"/>
    <child  link="right_pad4"/>
    <origin xyz="1.0 0 0" rpy="0 -1.57 0"/>
    <axis xyz="0 1 0"/>
    <limit effort="1000.0" lower="-3.14" upper="3.14" velocity="1000.0"/>
    <dynamics damping="0" friction="0"/>
  </joint>

  <link name="right_pad4">
    <collision name="right_pad4_collision">
      <origin xyz="0.5 0 -0.05" rpy="0 0 0"/>
      <geometry>
        <box size="1.0 1.0 0.1" />
      </geometry>
    </collision>
    <visual name="right_pad4_visual">
      <origin xyz="0.5 0 -0.05" rpy="0 0 0"/>
      <geometry>
        <box size="1.0 1.0 0.1" />
      </geometry>
      <material name="yellow"/>
    </visual>
    <xacro:box_inertial mass="0.5" origin="0.5 0 -0.05" d="1.0" w="1.0" h="0.1"/>
  </link>
  <gazebo reference="right_pad4">
    <material>Gazebo/Yellow</material>
    <mu1>100000</mu1>
    <mu2>100000</mu2>
    <kp>40000.0</kp>
    <kd>0.0</kd>
    <minDepth>0.0</minDepth>
    <maxContacts>5</maxContacts>
    <selfCollide>false</selfCollide>
    <dampingFactor>0.0</dampingFactor>
  </gazebo>

  <!-- This joint closes the loop. -->
  <joint name="connection_joint" type="continuous">
    <parent link="right_pad4"/>
    <child  link="dummy0_connection_right_pad1"/>
    <origin xyz="1.0 0 0" rpy="0 -1.57 0"/>
    <axis xyz="0 1 0"/>
  </joint>
  <!-- Dummy of the first link. -->
  <!-- Pleanse input relative joint pose from CHILD link in inertial origin -->
  <link name="dummy0_connection_right_pad1">
    <inertial>
      <mass value="0.0005"/>
      <origin xyz="0 0 0" rpy="0 0 0"/>
      <inertia
        ixx="0.00000001"
        ixy="0.00000000" iyy="0.00000001"
        ixz="0.00000000" iyz="0.00000000" izz="0.00000001"/>
    </inertial>
  </link>
  <joint name="origin_joint" type="continuous">
    <parent link="dummy0_connection_right_pad1"/>
    <child  link="dummy0_origin_right_pad1"/>
    <origin xyz="0 0 -0.5" rpy="0 0 0"/>
    <axis xyz="0 1 0"/>
  </joint>
  <link name="dummy0_origin_right_pad1">
    <inertial>
      <mass value="0.0005"/>
      <origin xyz="0 0 0" rpy="0 0 0"/>
      <inertia
        ixx="0.00000001"
        ixy="0.00000000" iyy="0.00000001"
        ixz="0.00000000" iyz="0.00000000" izz="0.00000001"/>
    </inertial>
  </link>
</robot>

