<?xml version="1.0" ?>
<!-- =================================================================================== -->
<!-- |    This document was autogenerated by xacro from leg_l_test.urdf.xacro          | -->
<!-- |    EDITING THIS FILE BY HAND IS NOT RECOMMENDED                                 | -->
<!-- =================================================================================== -->
<robot name="ginko" xmlns:xacro="http://www.ros.org/wiki/xacro">

  <link name="leg_l_link0">
    <!-- Collision created from STL mesh without color -->
    <collision>
      <origin rpy="0 0 0" xyz="0 0 0"/>
      <geometry>
        <mesh filename="package://ginko_description/meshes/stl/link02_l_femoral.stl"/>
      </geometry>
    </collision>
    <!-- Visualisation created from Color dae -->
    <visual>
      <origin rpy="0 0 0" xyz="0 0 0"/>
      <geometry>
        <mesh filename="package://ginko_description/meshes/stl/link02_l_femoral.stl"/>
        <!-- <mesh filename="package://ginko_description/models/ginko_auto/meshes/dae/link02_l_femoral.dae"/> -->
      </geometry>
    </visual>
    <inertial>
      <mass value="0.03433352"/>
      <origin rpy="0 0 0" xyz="0.02930795 0.03723759 -0.02605386"/>
      <inertia ixx="0.00002443" ixy="-0.00000021" ixz="-0.00000021" iyy="0.00002287" iyz="-0.00000391" izz="0.00002983"/>
    </inertial>
  </link>

  <!-- parallel link (upper-1st) -->
  <link name="leg_l_link1">
    <!-- Collision created from STL mesh without color -->
    <collision>
      <origin rpy="0 0 0" xyz="0 0 0"/>
      <geometry>
        <mesh filename="package://ginko_description/meshes/stl/link03_l_leg01.stl"/>
      </geometry>
    </collision>
    <!-- Visualisation created from Color dae -->
    <visual>
      <origin rpy="0 0 0" xyz="0 0 0"/>
      <geometry>
        <mesh filename="package://ginko_description/meshes/stl/link03_l_leg01.stl"/>
        <!-- <mesh filename="package://ginko_description/models/ginko_auto/meshes/dae/link03_l_leg01.dae"/> -->
      </geometry>
    </visual>
    <inertial>
      <mass value="0.18525692"/>
      <origin rpy="0 0 0" xyz="0.05000000 0.03285059 0.00068146"/>
      <inertia ixx="0.00041331" ixy="-0.00003605" ixz="-0.00000000" iyy="0.00027917" iyz="-0.00000184" izz="0.00066510"/>
    </inertial>
  </link>
  <joint name="leg_l_joint1" type="revolute">
    <parent link="leg_l_link0"/>
    <child link="leg_l_link1"/>
    <origin rpy="0 0.7854 0" xyz="0.0433 0.0175 -0.0481"/>
    <axis xyz="0 -1 0"/>
    <limit effort="1000.0" lower="-1.3" upper="0.7854" velocity="0.5"/>
  </joint>
  <!-- parallel link (upper-2nd) -->
  <link name="leg_l_link2">
    <!-- Collision created from STL mesh without color -->
    <collision>
      <origin rpy="0 0 0" xyz="0 0 0"/>
      <geometry>
        <mesh filename="package://ginko_description/meshes/stl/link04_l_leg02.stl"/>
      </geometry>
    </collision>
    <!-- Visualisation created from Color dae -->
    <visual>
      <origin rpy="0 0 0" xyz="0 0 0"/>
      <geometry>
        <mesh filename="package://ginko_description/meshes/stl/link04_l_leg02.stl"/>
        <!-- <mesh filename="package://ginko_description/models/ginko_auto/meshes/dae/link04_l_leg02.dae"/> -->
      </geometry>
    </visual>
    <inertial>
      <mass value="0.01646643"/>
      <origin rpy="0 0 0" xyz="0.05000000 0.02495100 -0.00491150"/>
      <inertia ixx="0.00000640" ixy="0.00000000" ixz="0.00000000" iyy="0.00001642" iyz="0.00000000" izz="0.00002264"/>
    </inertial>
  </link>
  <joint name="leg_l_joint2" type="revolute">
    <parent link="leg_l_link0"/>
    <child link="leg_l_link2"/>
    <origin rpy="0 0.7854 0" xyz="0.022 0.0175 -0.06015"/>
    <axis xyz="0 -1 0"/>
    <limit effort="1000.0" lower="-3.141593" upper="3.141593" velocity="0.5"/>
  </joint>
  <!-- knee -->
  <link name="leg_l_link3">
    <collision>
      <origin rpy="0 0 0" xyz="0 0 0"/>
      <geometry>
        <mesh filename="package://ginko_description/meshes/stl/link05_l_knee.stl"/>
      </geometry>
    </collision>
    <visual>
      <origin rpy="0 0 0" xyz="0 0 0"/>
      <geometry>
        <mesh filename="package://ginko_description/meshes/stl/link05_l_knee.stl"/>
        <!-- <mesh filename="package://ginko_description/models/ginko_auto/meshes/dae/link05_l_knee.dae"/> -->
      </geometry>
    </visual>
    <inertial>
      <mass value="0.01781176"/>
      <origin rpy="0 0 0" xyz="0.00393357 0.02364163 -0.01930000"/>
      <inertia ixx="0.00001301" ixy="0.00000008" ixz="0.00000000" iyy="0.00000700" iyz="0.00000000" izz="0.00001388"/>
    </inertial>
  </link>
<!--   <joint name="leg_l_joint3" type="revolute">
    <parent link="leg_l_link1"/>
    <child link="leg_l_link3"/>
    <origin rpy="0 -0.7854 0" xyz="0.1 0.0 0.0"/>
    <axis xyz="0 1 0"/>
    <limit effort="1000.0" lower="-3.141593" upper="3.141593" velocity="0.5"/>
  </joint> -->
  <joint name="leg_l_joint3_sub" type="revolute">
    <parent link="leg_l_link2"/>
    <child link="leg_l_link3"/>
    <origin rpy="0 -0.7854 0" xyz="0.1 0.0 0.0"/>
    <axis xyz="0 1 0"/>
    <limit effort="1000.0" lower="-3.141593" upper="3.141593" velocity="0.5"/>
  </joint>
  <!-- parallel link (lower-1st) -->
  <link name="leg_l_link4">
    <collision>
      <origin rpy="0 0 0" xyz="0 0 0"/>
      <geometry>
        <mesh filename="package://ginko_description/meshes/stl/link03_l_leg01.stl"/>
      </geometry>
    </collision>
    <visual>
      <origin rpy="0 0 0" xyz="0 0 0"/>
      <geometry>
        <mesh filename="package://ginko_description/meshes/stl/link03_l_leg01.stl"/>
      </geometry>
    </visual>
    <inertial>
      <mass value="0.18525692"/>
      <origin rpy="0 0 0" xyz="0.05000000 0.03285059 0.00068146"/>
      <inertia ixx="0.00041331" ixy="-0.00003605" ixz="-0.00000000" iyy="0.00027917" iyz="-0.00000184" izz="0.00066510"/>
    </inertial>
  </link>
  <joint name="leg_l_joint4" type="revolute">
    <parent link="leg_l_link3"/>
    <child link="leg_l_link4"/>
    <origin rpy="0 2.3562 0" xyz="0 0 -0.0386"/>
    <axis xyz="0 -1 0"/>
    <limit effort="1000.0" lower="-0.7854" upper="1.3" velocity="0.5"/>
  </joint>
  <!-- parallel link (lower-2nd) -->
  <link name="leg_l_link5">
    <collision>
      <origin rpy="0 0 0" xyz="0 0 0"/>
      <geometry>
        <mesh filename="package://ginko_description/meshes/stl/link04_l_leg02.stl"/>
      </geometry>
    </collision>
    <visual>
      <origin rpy="0 0 0" xyz="0 0 0"/>
      <geometry>
        <mesh filename="package://ginko_description/meshes/stl/link04_l_leg02.stl"/>
      </geometry>
    </visual>
    <inertial>
      <mass value="0.01646643"/>
      <origin rpy="0 0 0" xyz="0.05000000 0.02495100 -0.00491150"/>
      <inertia ixx="0.00000640" ixy="0.00000000" ixz="0.00000000" iyy="0.00001642" iyz="0.00000000" izz="0.00002264"/>
    </inertial>
  </link>
  <joint name="leg_l_joint5" type="revolute">
    <parent link="leg_l_link3"/>
    <child link="leg_l_link5"/>
    <origin rpy="0 2.3562 0" xyz="-0.0213 0 -0.02655"/>
    <axis xyz="0 -1 0"/>
    <limit effort="1000.0" lower="-3.141593" upper="3.141593" velocity="0.5"/>
  </joint>
  <!-- toe -->
  <link name="leg_l_link6">
    <collision>
      <origin rpy="0 0 0" xyz="0 0 0"/>
      <geometry>
        <mesh filename="package://ginko_description/meshes/stl/link06_l_toe01.stl"/>
      </geometry>
    </collision>
    <visual>
      <origin rpy="0 0 0" xyz="0 0 0"/>
      <geometry>
        <mesh filename="package://ginko_description/meshes/stl/link06_l_toe01.stl"/>
      </geometry>
    </visual>
    <inertial>
      <mass value="0.08799204"/>
      <origin rpy="0 0 0" xyz="-0.04166125 0.02463880 -0.02586249"/>
      <inertia ixx="0.00002815" ixy="-0.00000041" ixz="0.00000980" iyy="0.00006846" iyz="-0.00000026" izz="0.00006529"/>
    </inertial>
  </link>
<!--   <joint name="leg_l_joint6" type="revolute">
    <parent link="leg_l_link4"/>
    <child link="leg_l_link6"/>
    <origin rpy="0 -2.3562 0" xyz="0.1 0.0 0.0"/>
    <axis xyz="0 1 0"/>
    <limit effort="1000.0" lower="-3.141593" upper="3.141593" velocity="0.5"/>
  </joint> -->
  <joint name="leg_l_joint6_sub" type="revolute">
    <parent link="leg_l_link5"/>
    <child link="leg_l_link6"/>
    <origin rpy="0 -2.3562 0" xyz="0.1 0.0 0.0"/>
    <axis xyz="0 1 0"/>
    <limit effort="1000.0" lower="-3.141593" upper="3.141593" velocity="0.5"/>
  </joint>
  <link name="leg_l_link7">
    <collision>
      <origin rpy="0 0 0" xyz="0 0 0"/>
      <geometry>
        <mesh filename="package://ginko_description/meshes/stl/link07_l_toe02.stl"/>
      </geometry>
    </collision>
    <visual>
      <origin rpy="0 0 0" xyz="0 0 0"/>
      <geometry>
        <mesh filename="package://ginko_description/meshes/stl/link07_l_toe02.stl"/>
      </geometry>
    </visual>
    <inertial>
      <mass value="0.10920041"/>
      <origin rpy="0 0 0" xyz="0.02658756 0.00000053 -0.01782468"/>
      <inertia ixx="0.00003853" ixy="0.00000000" ixz="-0.00000479" iyy="0.00005192" iyz="0.00000000" izz="0.00003521"/>
    </inertial>
  </link>
  <joint name="leg_l_joint7" type="revolute">
    <parent link="leg_l_link6"/>
    <child link="leg_l_link7"/>
    <origin rpy="0 0 0" xyz="-0.028 0.02475 -0.0391"/>
    <axis xyz="-1 0 0"/>
    <limit effort="1000.0" lower="-1.6" upper="1.6" velocity="0.5"/>
  </joint>
  <link name="leg_l_link8">
    <collision>
      <origin rpy="0 0 0" xyz="0 0 0"/>
      <geometry>
        <mesh filename="package://ginko_description/meshes/stl/link08_l_toe03.stl"/>
      </geometry>
    </collision>
    <visual>
      <origin rpy="0 0 0" xyz="0 0 0"/>
      <geometry>
        <mesh filename="package://ginko_description/meshes/stl/link08_l_toe03.stl"/>
      </geometry>
    </visual>
    <inertial>
      <mass value="0.05363111"/>
      <origin rpy="0 0 0" xyz="0.00000000 0.00000000 -0.00269342"/>
      <inertia ixx="0.00002877" ixy="0.00000000" ixz="0.00000000" iyy="0.00007083" iyz="-0.00000000" izz="0.00009934"/>
    </inertial>
  </link>
  <joint name="leg_l_joint8" type="revolute">
    <parent link="leg_l_link7"/>
    <child link="leg_l_link8"/>
    <origin rpy="0 0 0" xyz="0.0342 0 -0.04"/>
    <axis xyz="0 0 1"/>
    <limit effort="1000.0" lower="-2.6" upper="2.6" velocity="0.5"/>
  </joint>

</robot>
