<?xml version="1.0" ?>
<!-- =================================================================================== -->
<!-- |    This document was autogenerated by xacro from ./../xacro/02_open_chain_and_dummy_link.xacro | -->
<!-- |    EDITING THIS FILE BY HAND IS NOT RECOMMENDED                                 | -->
<!-- =================================================================================== -->
<robot name="incorrect_xacro" xmlns:xacro="http://www.ros.org/wiki/xacro">
  <material name="red">
    <color rgba="1.0 0.0 0.0 1.0"/>
  </material>
  <material name="green">
    <color rgba="0.0 1.0 0.0 1.0"/>
  </material>
  <material name="blue">
    <color rgba="0.0 0.0 1.0 1.0"/>
  </material>
  <material name="yellow">
    <color rgba="1.0 1.0 0.0 1.0"/>
  </material>
  <link name="right_pad1">
    <collision name="right_pad1_collision">
      <origin rpy="0 0 0" xyz="0.5 0 0.25"/>
      <geometry>
        <box size="1.0 1.0 0.5"/>
      </geometry>
    </collision>
    <visual name="right_pad1_visual">
      <origin rpy="0 0 0" xyz="0.5 0 0.25"/>
      <geometry>
        <box size="1.0 1.0 0.5"/>
      </geometry>
      <material name="red"/>
    </visual>
    <inertial>
      <mass value="0.5"/>
      <origin rpy="0 0 0" xyz="0.5 0 0.25"/>
      <inertia ixx="0.0001" ixy="0.0000" ixz="0.0000" iyy="0.0001" iyz="0.0000" izz="0.0001"/>
    </inertial>
  </link>
  <!-- Joints are respect the PARENT in XACRO/URDF -->
  <!-- Joints are respect the CHILD in SDF -->
  <joint name="right_pad1_joint" type="revolute">
    <parent link="right_pad1"/>
    <child link="right_pad2"/>
    <origin rpy="0 -1.57 0" xyz="1.0 0 0.5"/>
    <axis xyz="0 1 0"/>
    <limit effort="1000.0" lower="-3.14" upper="3.14" velocity="1000.0"/>
    <dynamics damping="0" friction="0"/>
  </joint>
  <link name="right_pad2">
    <collision name="right_pad2_collision">
      <origin rpy="0 0 0" xyz="0.5 0 -0.05"/>
      <geometry>
        <box size="1.0 1.0 0.1"/>
      </geometry>
    </collision>
    <visual name="right_pad2_visual">
      <origin rpy="0 0 0" xyz="0.5 0 -0.05"/>
      <geometry>
        <box size="1.0 1.0 0.1"/>
      </geometry>
      <material name="green"/>
    </visual>
    <inertial>
      <mass value="0.5"/>
      <origin rpy="0 0 0" xyz="0.5 0 -0.05"/>
      <inertia ixx="0.0001" ixy="0.0000" ixz="0.0000" iyy="0.0001" iyz="0.0000" izz="0.0001"/>
    </inertial>
  </link>
  <joint name="right_pad2_joint" type="revolute">
    <parent link="right_pad2"/>
    <child link="right_pad3"/>
    <origin rpy="0 -1.57 0" xyz="1.0 0 0"/>
    <axis xyz="0 1 0"/>
    <limit effort="1000.0" lower="-3.14" upper="3.14" velocity="1000.0"/>
    <dynamics damping="0" friction="0"/>
  </joint>
  <link name="right_pad3">
    <collision name="right_pad3_collision">
      <origin rpy="0 0 0" xyz="0.5 0 -0.05"/>
      <geometry>
        <box size="1.0 1.0 0.1"/>
      </geometry>
    </collision>
    <visual name="right_pad3_visual">
      <origin rpy="0 0 0" xyz="0.5 0 -0.05"/>
      <geometry>
        <box size="1.0 1.0 0.1"/>
      </geometry>
      <material name="blue"/>
    </visual>
    <inertial>
      <mass value="0.5"/>
      <origin rpy="0 0 0" xyz="0.5 0 -0.05"/>
      <inertia ixx="0.0001" ixy="0.0000" ixz="0.0000" iyy="0.0001" iyz="0.0000" izz="0.0001"/>
    </inertial>
  </link>
  <joint name="right_pad3_joint" type="revolute">
    <parent link="right_pad3"/>
    <child link="right_pad4"/>
    <origin rpy="0 -1.57 0" xyz="1.0 0 0"/>
    <axis xyz="0 1 0"/>
    <limit effort="1000.0" lower="-3.14" upper="3.14" velocity="1000.0"/>
    <dynamics damping="0" friction="0"/>
  </joint>
  <link name="right_pad4">
    <collision name="right_pad4_collision">
      <origin rpy="0 0 0" xyz="0.5 0 -0.05"/>
      <geometry>
        <box size="1.0 1.0 0.1"/>
      </geometry>
    </collision>
    <visual name="right_pad4_visual">
      <origin rpy="0 0 0" xyz="0.5 0 -0.05"/>
      <geometry>
        <box size="1.0 1.0 0.1"/>
      </geometry>
      <material name="yellow"/>
    </visual>
    <inertial>
      <mass value="0.5"/>
      <origin rpy="0 0 0" xyz="0.5 0 -0.05"/>
      <inertia ixx="0.0001" ixy="0.0000" ixz="0.0000" iyy="0.0001" iyz="0.0000" izz="0.0001"/>
    </inertial>
  </link>
  <!-- This joint closes the loop. -->
  <joint name="connection_joint" type="continuous">
    <parent link="right_pad4"/>
    <child link="dummy0_connection_right_pad1"/>
    <origin rpy="0 -1.57 0" xyz="1.0 0 0"/>
    <axis xyz="0 1 0"/>
  </joint>
  <!-- Dummy of he first link. -->
  <!-- Pleanse input relative joint pose from CHILD link in inertial origin -->
  <link name="dummy0_connection_right_pad1">
    <inertial>
      <mass value="0.0005"/>
      <origin rpy="0 0 0" xyz="0 0 0"/>
      <inertia ixx="0.00000001" ixy="0.00000000" ixz="0.00000000" iyy="0.00000001" iyz="0.00000000" izz="0.00000001"/>
    </inertial>
  </link>
  <joint name="origin_joint" type="continuous">
    <parent link="dummy0_connection_right_pad1"/>
    <child link="dummy0_origin_right_pad1"/>
    <origin rpy="0 0 0" xyz="0 0 -0.5"/>
    <axis xyz="0 1 0"/>
  </joint>
  <link name="dummy0_origin_right_pad1">
    <inertial>
      <mass value="0.0005"/>
      <origin rpy="0 0 0" xyz="0 0 0"/>
      <inertia ixx="0.00000001" ixy="0.00000000" ixz="0.00000000" iyy="0.00000001" iyz="0.00000000" izz="0.00000001"/>
    </inertial>
  </link>
</robot>
