<sdf version='1.6'>
  <model name='incorrect_xacro'>
    <link name='right_pad1'>
      <pose frame=''>0 0 0 0 -0 0</pose>
      <inertial>
        <pose frame=''>0.5 0 0.25 0 -0 0</pose>
        <mass>0.5</mass>
        <inertia>
          <ixx>0.0001</ixx>
          <ixy>0</ixy>
          <ixz>0</ixz>
          <iyy>0.0001</iyy>
          <iyz>0</iyz>
          <izz>0.0001</izz>
        </inertia>
      </inertial>
      <collision name='right_pad1_collision_collision'>
        <pose frame=''>0.5 0 0.25 0 -0 0</pose>
        <geometry>
          <box>
            <size>1 1 0.5</size>
          </box>
        </geometry>
      </collision>
      <visual name='right_pad1_visual_visual'>
        <pose frame=''>0.5 0 0.25 0 -0 0</pose>
        <geometry>
          <box>
            <size>1 1 0.5</size>
          </box>
        </geometry>
      </visual>
    </link>
    <link name='right_pad2'>
      <pose frame=''>1 0 0.5 0 -1.57 0</pose>
      <inertial>
        <pose frame=''>0.5 0 -0.05 0 -0 0</pose>
        <mass>0.5</mass>
        <inertia>
          <ixx>0.0001</ixx>
          <ixy>0</ixy>
          <ixz>0</ixz>
          <iyy>0.0001</iyy>
          <iyz>0</iyz>
          <izz>0.0001</izz>
        </inertia>
      </inertial>
      <collision name='right_pad2_collision_collision'>
        <pose frame=''>0.5 0 -0.05 0 -0 0</pose>
        <geometry>
          <box>
            <size>1 1 0.1</size>
          </box>
        </geometry>
      </collision>
      <visual name='right_pad2_visual_visual'>
        <pose frame=''>0.5 0 -0.05 0 -0 0</pose>
        <geometry>
          <box>
            <size>1 1 0.1</size>
          </box>
        </geometry>
      </visual>
    </link>
    <joint name='right_pad1_joint' type='revolute'>
      <child>right_pad2</child>
      <parent>right_pad1</parent>
      <axis>
        <xyz>0 1 0</xyz>
        <limit>
          <lower>-3.14</lower>
          <upper>3.14</upper>
          <effort>1000</effort>
          <velocity>1000</velocity>
        </limit>
        <dynamics>
          <damping>0</damping>
          <friction>0</friction>
          <spring_reference>0</spring_reference>
          <spring_stiffness>0</spring_stiffness>
        </dynamics>
        <use_parent_model_frame>1</use_parent_model_frame>
      </axis>
    </joint>
    <link name='right_pad3'>
      <pose frame=''>1.0008 0 1.5 3.14159 -0.001593 3.14159</pose>
      <inertial>
        <pose frame=''>0.5 0 -0.05 0 -0 0</pose>
        <mass>0.5</mass>
        <inertia>
          <ixx>0.0001</ixx>
          <ixy>0</ixy>
          <ixz>0</ixz>
          <iyy>0.0001</iyy>
          <iyz>0</iyz>
          <izz>0.0001</izz>
        </inertia>
      </inertial>
      <collision name='right_pad3_collision_collision'>
        <pose frame=''>0.5 0 -0.05 0 -0 0</pose>
        <geometry>
          <box>
            <size>1 1 0.1</size>
          </box>
        </geometry>
      </collision>
      <visual name='right_pad3_visual_visual'>
        <pose frame=''>0.5 0 -0.05 0 -0 0</pose>
        <geometry>
          <box>
            <size>1 1 0.1</size>
          </box>
        </geometry>
      </visual>
    </link>
    <joint name='right_pad2_joint' type='revolute'>
      <child>right_pad3</child>
      <parent>right_pad2</parent>
      <axis>
        <xyz>0 1 0</xyz>
        <limit>
          <lower>-3.14</lower>
          <upper>3.14</upper>
          <effort>1000</effort>
          <velocity>1000</velocity>
        </limit>
        <dynamics>
          <damping>0</damping>
          <friction>0</friction>
          <spring_reference>0</spring_reference>
          <spring_stiffness>0</spring_stiffness>
        </dynamics>
        <use_parent_model_frame>1</use_parent_model_frame>
      </axis>
    </joint>
    <link name='right_pad4'>
      <pose frame=''>0.000798 0 1.50159 -3.14159 1.56841 -3.14159</pose>
      <inertial>
        <pose frame=''>0.5 0 -0.05 0 -0 0</pose>
        <mass>0.5</mass>
        <inertia>
          <ixx>0.0001</ixx>
          <ixy>0</ixy>
          <ixz>0</ixz>
          <iyy>0.0001</iyy>
          <iyz>0</iyz>
          <izz>0.0001</izz>
        </inertia>
      </inertial>
      <collision name='right_pad4_collision_collision'>
        <pose frame=''>0.5 0 -0.05 0 -0 0</pose>
        <geometry>
          <box>
            <size>1 1 0.1</size>
          </box>
        </geometry>
      </collision>
      <visual name='right_pad4_visual_visual'>
        <pose frame=''>0.5 0 -0.05 0 -0 0</pose>
        <geometry>
          <box>
            <size>1 1 0.1</size>
          </box>
        </geometry>
      </visual>
    </link>
    <joint name='right_pad3_joint' type='revolute'>
      <child>right_pad4</child>
      <parent>right_pad3</parent>
      <axis>
        <xyz>0 1 -0</xyz>
        <limit>
          <lower>-3.14</lower>
          <upper>3.14</upper>
          <effort>1000</effort>
          <velocity>1000</velocity>
        </limit>
        <dynamics>
          <damping>0</damping>
          <friction>0</friction>
          <spring_reference>0</spring_reference>
          <spring_stiffness>0</spring_stiffness>
        </dynamics>
        <use_parent_model_frame>1</use_parent_model_frame>
      </axis>
    </joint>
    <joint name='connection_joint' type='revolute'>
      <pose>-0.001591 0 0.501595 0 0.003185 0</pose>
      <child>right_pad1</child>
      <parent>right_pad4</parent>
      <axis>
        <xyz>0 1 -0</xyz>
        <limit>
          <lower>-1e+16</lower>
          <upper>1e+16</upper>
        </limit>
        <dynamics>
          <spring_reference>0</spring_reference>
          <spring_stiffness>0</spring_stiffness>
        </dynamics>
        <use_parent_model_frame>1</use_parent_model_frame>
      </axis>
    </joint>
  </model>
</sdf>
