<sdf version='1.6'>
  <model name='ginko'>
    <link name='leg_l_link0'>
      <pose frame=''>0 0 0 0 -0 0</pose>
      <inertial>
        <pose frame=''>0.029308 0.037238 -0.026054 0 -0 0</pose>
        <mass>0.0343335</mass>
        <inertia>
          <ixx>2.443e-05</ixx>
          <ixy>-2.1e-07</ixy>
          <ixz>-2.1e-07</ixz>
          <iyy>2.287e-05</iyy>
          <iyz>-3.91e-06</iyz>
          <izz>2.983e-05</izz>
        </inertia>
      </inertial>
      <collision name='leg_l_link0_collision'>
        <pose frame=''>0 0 0 0 -0 0</pose>
        <geometry>
          <mesh>
            <scale>1 1 1</scale>
            <uri>model://link02_l_femoral.stl</uri>
          </mesh>
        </geometry>
      </collision>
      <visual name='leg_l_link0_visual'>
        <pose frame=''>0 0 0 0 -0 0</pose>
        <geometry>
          <mesh>
            <scale>1 1 1</scale>
            <uri>model://link02_l_femoral.stl</uri>
          </mesh>
        </geometry>
      </visual>
    </link>
    <link name='leg_l_link1'>
      <pose frame=''>0.0433 0.0175 -0.0481 0 0.7854 0</pose>
      <inertial>
        <pose frame=''>0.05 0.032851 0.000681 0 -0 0</pose>
        <mass>0.185257</mass>
        <inertia>
          <ixx>0.00041331</ixx>
          <ixy>-3.605e-05</ixy>
          <ixz>-0</ixz>
          <iyy>0.00027917</iyy>
          <iyz>-1.84e-06</iyz>
          <izz>0.0006651</izz>
        </inertia>
      </inertial>
      <collision name='leg_l_link1_collision'>
        <pose frame=''>0 0 0 0 -0 0</pose>
        <geometry>
          <mesh>
            <scale>1 1 1</scale>
            <uri>model://link03_l_leg01.stl</uri>
          </mesh>
        </geometry>
      </collision>
      <visual name='leg_l_link1_visual'>
        <pose frame=''>0 0 0 0 -0 0</pose>
        <geometry>
          <mesh>
            <scale>1 1 1</scale>
            <uri>model://link03_l_leg01.stl</uri>
          </mesh>
        </geometry>
      </visual>
    </link>
    <joint name='leg_l_joint1' type='revolute'>
      <child>leg_l_link1</child>
      <parent>leg_l_link0</parent>
      <axis>
        <xyz>0 -1 0</xyz>
        <limit>
          <lower>-1.3</lower>
          <upper>0.7854</upper>
          <effort>1000</effort>
          <velocity>0.5</velocity>
        </limit>
        <dynamics>
          <spring_reference>0</spring_reference>
          <spring_stiffness>0</spring_stiffness>
        </dynamics>
        <use_parent_model_frame>1</use_parent_model_frame>
      </axis>
    </joint>
    <link name='leg_l_link3'>
      <pose frame=''>0.114011 0.0175 -0.118811 0 -0 0</pose>
      <inertial>
        <pose frame=''>0.003934 0.023642 -0.0193 0 -0 0</pose>
        <mass>0.0178118</mass>
        <inertia>
          <ixx>1.301e-05</ixx>
          <ixy>8e-08</ixy>
          <ixz>0</ixz>
          <iyy>7e-06</iyy>
          <iyz>0</iyz>
          <izz>1.388e-05</izz>
        </inertia>
      </inertial>
      <collision name='leg_l_link3_collision'>
        <pose frame=''>0 0 0 0 -0 0</pose>
        <geometry>
          <mesh>
            <scale>1 1 1</scale>
            <uri>model://link05_l_knee.stl</uri>
          </mesh>
        </geometry>
      </collision>
      <visual name='leg_l_link3_visual'>
        <pose frame=''>0 0 0 0 -0 0</pose>
        <geometry>
          <mesh>
            <scale>1 1 1</scale>
            <uri>model://link05_l_knee.stl</uri>
          </mesh>
        </geometry>
      </visual>
    </link>
    <joint name='leg_l_joint3_sub' type='revolute'>
      <child>leg_l_link3</child>
      <parent>leg_l_link2</parent>
      <axis>
        <xyz>0 1 0</xyz>
        <limit>
          <lower>-3.14159</lower>
          <upper>3.14159</upper>
          <effort>1000</effort>
          <velocity>0.5</velocity>
        </limit>
        <dynamics>
          <spring_reference>0</spring_reference>
          <spring_stiffness>0</spring_stiffness>
        </dynamics>
        <use_parent_model_frame>1</use_parent_model_frame>
      </axis>
    </joint>
    <link name='leg_l_link4'>
      <pose frame=''>0.114011 0.0175 -0.157411 3.14159 0.785393 3.14159</pose>
      <inertial>
        <pose frame=''>0.05 0.032851 0.000681 0 -0 0</pose>
        <mass>0.185257</mass>
        <inertia>
          <ixx>0.00041331</ixx>
          <ixy>-3.605e-05</ixy>
          <ixz>-0</ixz>
          <iyy>0.00027917</iyy>
          <iyz>-1.84e-06</iyz>
          <izz>0.0006651</izz>
        </inertia>
      </inertial>
      <collision name='leg_l_link4_collision'>
        <pose frame=''>0 0 0 0 -0 0</pose>
        <geometry>
          <mesh>
            <scale>1 1 1</scale>
            <uri>model://link03_l_leg01.stl</uri>
          </mesh>
        </geometry>
      </collision>
      <visual name='leg_l_link4_visual'>
        <pose frame=''>0 0 0 0 -0 0</pose>
        <geometry>
          <mesh>
            <scale>1 1 1</scale>
            <uri>model://link03_l_leg01.stl</uri>
          </mesh>
        </geometry>
      </visual>
    </link>
    <joint name='leg_l_joint4' type='revolute'>
      <child>leg_l_link4</child>
      <parent>leg_l_link3</parent>
      <axis>
        <xyz>0 -1 0</xyz>
        <limit>
          <lower>-0.7854</lower>
          <upper>1.3</upper>
          <effort>1000</effort>
          <velocity>0.5</velocity>
        </limit>
        <dynamics>
          <spring_reference>0</spring_reference>
          <spring_stiffness>0</spring_stiffness>
        </dynamics>
        <use_parent_model_frame>1</use_parent_model_frame>
      </axis>
    </joint>
    <link name='leg_l_link6'>
      <pose frame=''>0.0433 0.0175 -0.228121 0 -0 0</pose>
      <inertial>
        <pose frame=''>-0.041661 0.024639 -0.025863 0 -0 0</pose>
        <mass>0.087992</mass>
        <inertia>
          <ixx>2.815e-05</ixx>
          <ixy>-4.1e-07</ixy>
          <ixz>9.8e-06</ixz>
          <iyy>6.846e-05</iyy>
          <iyz>-2.6e-07</iyz>
          <izz>6.529e-05</izz>
        </inertia>
      </inertial>
      <collision name='leg_l_link6_collision'>
        <pose frame=''>0 0 0 0 -0 0</pose>
        <geometry>
          <mesh>
            <scale>1 1 1</scale>
            <uri>model://link06_l_toe01.stl</uri>
          </mesh>
        </geometry>
      </collision>
      <visual name='leg_l_link6_visual'>
        <pose frame=''>0 0 0 0 -0 0</pose>
        <geometry>
          <mesh>
            <scale>1 1 1</scale>
            <uri>model://link06_l_toe01.stl</uri>
          </mesh>
        </geometry>
      </visual>
    </link>
    <joint name='leg_l_joint6_sub' type='revolute'>
      <child>leg_l_link6</child>
      <parent>leg_l_link5</parent>
      <axis>
        <xyz>0 1 0</xyz>
        <limit>
          <lower>-3.14159</lower>
          <upper>3.14159</upper>
          <effort>1000</effort>
          <velocity>0.5</velocity>
        </limit>
        <dynamics>
          <spring_reference>0</spring_reference>
          <spring_stiffness>0</spring_stiffness>
        </dynamics>
        <use_parent_model_frame>1</use_parent_model_frame>
      </axis>
    </joint>
    <link name='leg_l_link7'>
      <pose frame=''>0.0153 0.04225 -0.267221 0 -0 0</pose>
      <inertial>
        <pose frame=''>0.026588 1e-06 -0.017825 0 -0 0</pose>
        <mass>0.1092</mass>
        <inertia>
          <ixx>3.853e-05</ixx>
          <ixy>0</ixy>
          <ixz>-4.79e-06</ixz>
          <iyy>5.192e-05</iyy>
          <iyz>0</iyz>
          <izz>3.521e-05</izz>
        </inertia>
      </inertial>
      <collision name='leg_l_link7_collision'>
        <pose frame=''>0 0 0 0 -0 0</pose>
        <geometry>
          <mesh>
            <scale>1 1 1</scale>
            <uri>model://link07_l_toe02.stl</uri>
          </mesh>
        </geometry>
      </collision>
      <visual name='leg_l_link7_visual'>
        <pose frame=''>0 0 0 0 -0 0</pose>
        <geometry>
          <mesh>
            <scale>1 1 1</scale>
            <uri>model://link07_l_toe02.stl</uri>
          </mesh>
        </geometry>
      </visual>
    </link>
    <joint name='leg_l_joint7' type='revolute'>
      <child>leg_l_link7</child>
      <parent>leg_l_link6</parent>
      <axis>
        <xyz>-1 0 0</xyz>
        <limit>
          <lower>-1.6</lower>
          <upper>1.6</upper>
          <effort>1000</effort>
          <velocity>0.5</velocity>
        </limit>
        <dynamics>
          <spring_reference>0</spring_reference>
          <spring_stiffness>0</spring_stiffness>
        </dynamics>
        <use_parent_model_frame>1</use_parent_model_frame>
      </axis>
    </joint>
    <link name='leg_l_link8'>
      <pose frame=''>0.0495 0.04225 -0.307221 0 -0 0</pose>
      <inertial>
        <pose frame=''>0 0 -0.002693 0 -0 0</pose>
        <mass>0.0536311</mass>
        <inertia>
          <ixx>2.877e-05</ixx>
          <ixy>0</ixy>
          <ixz>0</ixz>
          <iyy>7.083e-05</iyy>
          <iyz>-0</iyz>
          <izz>9.934e-05</izz>
        </inertia>
      </inertial>
      <collision name='leg_l_link8_collision'>
        <pose frame=''>0 0 0 0 -0 0</pose>
        <geometry>
          <mesh>
            <scale>1 1 1</scale>
            <uri>model://link08_l_toe03.stl</uri>
          </mesh>
        </geometry>
      </collision>
      <visual name='leg_l_link8_visual'>
        <pose frame=''>0 0 0 0 -0 0</pose>
        <geometry>
          <mesh>
            <scale>1 1 1</scale>
            <uri>model://link08_l_toe03.stl</uri>
          </mesh>
        </geometry>
      </visual>
    </link>
    <joint name='leg_l_joint8' type='revolute'>
      <child>leg_l_link8</child>
      <parent>leg_l_link7</parent>
      <axis>
        <xyz>0 0 1</xyz>
        <limit>
          <lower>-2.6</lower>
          <upper>2.6</upper>
          <effort>1000</effort>
          <velocity>0.5</velocity>
        </limit>
        <dynamics>
          <spring_reference>0</spring_reference>
          <spring_stiffness>0</spring_stiffness>
        </dynamics>
        <use_parent_model_frame>1</use_parent_model_frame>
      </axis>
    </joint>
    <link name='leg_l_link5'>
      <pose frame=''>0.092711 0.0175 -0.145361 3.14159 0.785393 3.14159</pose>
      <inertial>
        <pose frame=''>0.05 0.024951 -0.004912 0 -0 0</pose>
        <mass>0.0164664</mass>
        <inertia>
          <ixx>6.4e-06</ixx>
          <ixy>0</ixy>
          <ixz>0</ixz>
          <iyy>1.642e-05</iyy>
          <iyz>0</iyz>
          <izz>2.264e-05</izz>
        </inertia>
      </inertial>
      <collision name='leg_l_link5_collision'>
        <pose frame=''>0 0 0 0 -0 0</pose>
        <geometry>
          <mesh>
            <scale>1 1 1</scale>
            <uri>model://link04_l_leg02.stl</uri>
          </mesh>
        </geometry>
      </collision>
      <visual name='leg_l_link5_visual'>
        <pose frame=''>0 0 0 0 -0 0</pose>
        <geometry>
          <mesh>
            <scale>1 1 1</scale>
            <uri>model://link04_l_leg02.stl</uri>
          </mesh>
        </geometry>
      </visual>
    </link>
    <joint name='leg_l_joint5' type='revolute'>
      <child>leg_l_link5</child>
      <parent>leg_l_link3</parent>
      <axis>
        <xyz>0 -1 0</xyz>
        <limit>
          <lower>-3.14159</lower>
          <upper>3.14159</upper>
          <effort>1000</effort>
          <velocity>0.5</velocity>
        </limit>
        <dynamics>
          <spring_reference>0</spring_reference>
          <spring_stiffness>0</spring_stiffness>
        </dynamics>
        <use_parent_model_frame>1</use_parent_model_frame>
      </axis>
    </joint>
    <link name='leg_l_link6'>
      <pose frame=''>0.022 0.0175 -0.216071 0 -0 0</pose>
      <inertial>
        <pose frame=''>-0.041661 0.024639 -0.025863 0 -0 0</pose>
        <mass>0.087992</mass>
        <inertia>
          <ixx>2.815e-05</ixx>
          <ixy>-4.1e-07</ixy>
          <ixz>9.8e-06</ixz>
          <iyy>6.846e-05</iyy>
          <iyz>-2.6e-07</iyz>
          <izz>6.529e-05</izz>
        </inertia>
      </inertial>
      <collision name='leg_l_link6_collision'>
        <pose frame=''>0 0 0 0 -0 0</pose>
        <geometry>
          <mesh>
            <scale>1 1 1</scale>
            <uri>model://link06_l_toe01.stl</uri>
          </mesh>
        </geometry>
      </collision>
      <visual name='leg_l_link6_visual'>
        <pose frame=''>0 0 0 0 -0 0</pose>
        <geometry>
          <mesh>
            <scale>1 1 1</scale>
            <uri>model://link06_l_toe01.stl</uri>
          </mesh>
        </geometry>
      </visual>
    </link>
    <joint name='leg_l_joint6_sub' type='revolute'>
      <child>leg_l_link6</child>
      <parent>leg_l_link5</parent>
      <axis>
        <xyz>0 1 0</xyz>
        <limit>
          <lower>-3.14159</lower>
          <upper>3.14159</upper>
          <effort>1000</effort>
          <velocity>0.5</velocity>
        </limit>
        <dynamics>
          <spring_reference>0</spring_reference>
          <spring_stiffness>0</spring_stiffness>
        </dynamics>
        <use_parent_model_frame>1</use_parent_model_frame>
      </axis>
    </joint>
    <link name='leg_l_link7'>
      <pose frame=''>-0.006001 0.04225 -0.255171 0 -0 0</pose>
      <inertial>
        <pose frame=''>0.026588 1e-06 -0.017825 0 -0 0</pose>
        <mass>0.1092</mass>
        <inertia>
          <ixx>3.853e-05</ixx>
          <ixy>0</ixy>
          <ixz>-4.79e-06</ixz>
          <iyy>5.192e-05</iyy>
          <iyz>0</iyz>
          <izz>3.521e-05</izz>
        </inertia>
      </inertial>
      <collision name='leg_l_link7_collision'>
        <pose frame=''>0 0 0 0 -0 0</pose>
        <geometry>
          <mesh>
            <scale>1 1 1</scale>
            <uri>model://link07_l_toe02.stl</uri>
          </mesh>
        </geometry>
      </collision>
      <visual name='leg_l_link7_visual'>
        <pose frame=''>0 0 0 0 -0 0</pose>
        <geometry>
          <mesh>
            <scale>1 1 1</scale>
            <uri>model://link07_l_toe02.stl</uri>
          </mesh>
        </geometry>
      </visual>
    </link>
    <joint name='leg_l_joint7' type='revolute'>
      <child>leg_l_link7</child>
      <parent>leg_l_link6</parent>
      <axis>
        <xyz>-1 0 0</xyz>
        <limit>
          <lower>-1.6</lower>
          <upper>1.6</upper>
          <effort>1000</effort>
          <velocity>0.5</velocity>
        </limit>
        <dynamics>
          <spring_reference>0</spring_reference>
          <spring_stiffness>0</spring_stiffness>
        </dynamics>
        <use_parent_model_frame>1</use_parent_model_frame>
      </axis>
    </joint>
    <link name='leg_l_link8'>
      <pose frame=''>0.0282 0.04225 -0.295171 0 -0 0</pose>
      <inertial>
        <pose frame=''>0 0 -0.002693 0 -0 0</pose>
        <mass>0.0536311</mass>
        <inertia>
          <ixx>2.877e-05</ixx>
          <ixy>0</ixy>
          <ixz>0</ixz>
          <iyy>7.083e-05</iyy>
          <iyz>-0</iyz>
          <izz>9.934e-05</izz>
        </inertia>
      </inertial>
      <collision name='leg_l_link8_collision'>
        <pose frame=''>0 0 0 0 -0 0</pose>
        <geometry>
          <mesh>
            <scale>1 1 1</scale>
            <uri>model://link08_l_toe03.stl</uri>
          </mesh>
        </geometry>
      </collision>
      <visual name='leg_l_link8_visual'>
        <pose frame=''>0 0 0 0 -0 0</pose>
        <geometry>
          <mesh>
            <scale>1 1 1</scale>
            <uri>model://link08_l_toe03.stl</uri>
          </mesh>
        </geometry>
      </visual>
    </link>
    <joint name='leg_l_joint8' type='revolute'>
      <child>leg_l_link8</child>
      <parent>leg_l_link7</parent>
      <axis>
        <xyz>0 0 1</xyz>
        <limit>
          <lower>-2.6</lower>
          <upper>2.6</upper>
          <effort>1000</effort>
          <velocity>0.5</velocity>
        </limit>
        <dynamics>
          <spring_reference>0</spring_reference>
          <spring_stiffness>0</spring_stiffness>
        </dynamics>
        <use_parent_model_frame>1</use_parent_model_frame>
      </axis>
    </joint>
    <link name='leg_l_link2'>
      <pose frame=''>0.022 0.0175 -0.06015 0 0.7854 0</pose>
      <inertial>
        <pose frame=''>0.05 0.024951 -0.004912 0 -0 0</pose>
        <mass>0.0164664</mass>
        <inertia>
          <ixx>6.4e-06</ixx>
          <ixy>0</ixy>
          <ixz>0</ixz>
          <iyy>1.642e-05</iyy>
          <iyz>0</iyz>
          <izz>2.264e-05</izz>
        </inertia>
      </inertial>
      <collision name='leg_l_link2_collision'>
        <pose frame=''>0 0 0 0 -0 0</pose>
        <geometry>
          <mesh>
            <scale>1 1 1</scale>
            <uri>model://link04_l_leg02.stl</uri>
          </mesh>
        </geometry>
      </collision>
      <visual name='leg_l_link2_visual'>
        <pose frame=''>0 0 0 0 -0 0</pose>
        <geometry>
          <mesh>
            <scale>1 1 1</scale>
            <uri>model://link04_l_leg02.stl</uri>
          </mesh>
        </geometry>
      </visual>
    </link>
    <joint name='leg_l_joint2' type='revolute'>
      <child>leg_l_link2</child>
      <parent>leg_l_link0</parent>
      <axis>
        <xyz>0 -1 0</xyz>
        <limit>
          <lower>-3.14159</lower>
          <upper>3.14159</upper>
          <effort>1000</effort>
          <velocity>0.5</velocity>
        </limit>
        <dynamics>
          <spring_reference>0</spring_reference>
          <spring_stiffness>0</spring_stiffness>
        </dynamics>
        <use_parent_model_frame>1</use_parent_model_frame>
      </axis>
    </joint>
    <link name='leg_l_link3'>
      <pose frame=''>0.092711 0.0175 -0.130861 0 -0 0</pose>
      <inertial>
        <pose frame=''>0.003934 0.023642 -0.0193 0 -0 0</pose>
        <mass>0.0178118</mass>
        <inertia>
          <ixx>1.301e-05</ixx>
          <ixy>8e-08</ixy>
          <ixz>0</ixz>
          <iyy>7e-06</iyy>
          <iyz>0</iyz>
          <izz>1.388e-05</izz>
        </inertia>
      </inertial>
      <collision name='leg_l_link3_collision'>
        <pose frame=''>0 0 0 0 -0 0</pose>
        <geometry>
          <mesh>
            <scale>1 1 1</scale>
            <uri>model://link05_l_knee.stl</uri>
          </mesh>
        </geometry>
      </collision>
      <visual name='leg_l_link3_visual'>
        <pose frame=''>0 0 0 0 -0 0</pose>
        <geometry>
          <mesh>
            <scale>1 1 1</scale>
            <uri>model://link05_l_knee.stl</uri>
          </mesh>
        </geometry>
      </visual>
    </link>
    <joint name='leg_l_joint3_sub' type='revolute'>
      <child>leg_l_link3</child>
      <parent>leg_l_link2</parent>
      <axis>
        <xyz>0 1 0</xyz>
        <limit>
          <lower>-3.14159</lower>
          <upper>3.14159</upper>
          <effort>1000</effort>
          <velocity>0.5</velocity>
        </limit>
        <dynamics>
          <spring_reference>0</spring_reference>
          <spring_stiffness>0</spring_stiffness>
        </dynamics>
        <use_parent_model_frame>1</use_parent_model_frame>
      </axis>
    </joint>
    <link name='leg_l_link4'>
      <pose frame=''>0.092711 0.0175 -0.169461 3.14159 0.785393 3.14159</pose>
      <inertial>
        <pose frame=''>0.05 0.032851 0.000681 0 -0 0</pose>
        <mass>0.185257</mass>
        <inertia>
          <ixx>0.00041331</ixx>
          <ixy>-3.605e-05</ixy>
          <ixz>-0</ixz>
          <iyy>0.00027917</iyy>
          <iyz>-1.84e-06</iyz>
          <izz>0.0006651</izz>
        </inertia>
      </inertial>
      <collision name='leg_l_link4_collision'>
        <pose frame=''>0 0 0 0 -0 0</pose>
        <geometry>
          <mesh>
            <scale>1 1 1</scale>
            <uri>model://link03_l_leg01.stl</uri>
          </mesh>
        </geometry>
      </collision>
      <visual name='leg_l_link4_visual'>
        <pose frame=''>0 0 0 0 -0 0</pose>
        <geometry>
          <mesh>
            <scale>1 1 1</scale>
            <uri>model://link03_l_leg01.stl</uri>
          </mesh>
        </geometry>
      </visual>
    </link>
    <joint name='leg_l_joint4' type='revolute'>
      <child>leg_l_link4</child>
      <parent>leg_l_link3</parent>
      <axis>
        <xyz>0 -1 0</xyz>
        <limit>
          <lower>-0.7854</lower>
          <upper>1.3</upper>
          <effort>1000</effort>
          <velocity>0.5</velocity>
        </limit>
        <dynamics>
          <spring_reference>0</spring_reference>
          <spring_stiffness>0</spring_stiffness>
        </dynamics>
        <use_parent_model_frame>1</use_parent_model_frame>
      </axis>
    </joint>
    <link name='leg_l_link6'>
      <pose frame=''>0.022 0.0175 -0.240171 0 -0 0</pose>
      <inertial>
        <pose frame=''>-0.041661 0.024639 -0.025863 0 -0 0</pose>
        <mass>0.087992</mass>
        <inertia>
          <ixx>2.815e-05</ixx>
          <ixy>-4.1e-07</ixy>
          <ixz>9.8e-06</ixz>
          <iyy>6.846e-05</iyy>
          <iyz>-2.6e-07</iyz>
          <izz>6.529e-05</izz>
        </inertia>
      </inertial>
      <collision name='leg_l_link6_collision'>
        <pose frame=''>0 0 0 0 -0 0</pose>
        <geometry>
          <mesh>
            <scale>1 1 1</scale>
            <uri>model://link06_l_toe01.stl</uri>
          </mesh>
        </geometry>
      </collision>
      <visual name='leg_l_link6_visual'>
        <pose frame=''>0 0 0 0 -0 0</pose>
        <geometry>
          <mesh>
            <scale>1 1 1</scale>
            <uri>model://link06_l_toe01.stl</uri>
          </mesh>
        </geometry>
      </visual>
    </link>
    <joint name='leg_l_joint6_sub' type='revolute'>
      <child>leg_l_link6</child>
      <parent>leg_l_link5</parent>
      <axis>
        <xyz>0 1 0</xyz>
        <limit>
          <lower>-3.14159</lower>
          <upper>3.14159</upper>
          <effort>1000</effort>
          <velocity>0.5</velocity>
        </limit>
        <dynamics>
          <spring_reference>0</spring_reference>
          <spring_stiffness>0</spring_stiffness>
        </dynamics>
        <use_parent_model_frame>1</use_parent_model_frame>
      </axis>
    </joint>
    <link name='leg_l_link7'>
      <pose frame=''>-0.006001 0.04225 -0.279271 0 -0 0</pose>
      <inertial>
        <pose frame=''>0.026588 1e-06 -0.017825 0 -0 0</pose>
        <mass>0.1092</mass>
        <inertia>
          <ixx>3.853e-05</ixx>
          <ixy>0</ixy>
          <ixz>-4.79e-06</ixz>
          <iyy>5.192e-05</iyy>
          <iyz>0</iyz>
          <izz>3.521e-05</izz>
        </inertia>
      </inertial>
      <collision name='leg_l_link7_collision'>
        <pose frame=''>0 0 0 0 -0 0</pose>
        <geometry>
          <mesh>
            <scale>1 1 1</scale>
            <uri>model://link07_l_toe02.stl</uri>
          </mesh>
        </geometry>
      </collision>
      <visual name='leg_l_link7_visual'>
        <pose frame=''>0 0 0 0 -0 0</pose>
        <geometry>
          <mesh>
            <scale>1 1 1</scale>
            <uri>model://link07_l_toe02.stl</uri>
          </mesh>
        </geometry>
      </visual>
    </link>
    <joint name='leg_l_joint7' type='revolute'>
      <child>leg_l_link7</child>
      <parent>leg_l_link6</parent>
      <axis>
        <xyz>-1 0 0</xyz>
        <limit>
          <lower>-1.6</lower>
          <upper>1.6</upper>
          <effort>1000</effort>
          <velocity>0.5</velocity>
        </limit>
        <dynamics>
          <spring_reference>0</spring_reference>
          <spring_stiffness>0</spring_stiffness>
        </dynamics>
        <use_parent_model_frame>1</use_parent_model_frame>
      </axis>
    </joint>
    <link name='leg_l_link8'>
      <pose frame=''>0.0282 0.04225 -0.319271 0 -0 0</pose>
      <inertial>
        <pose frame=''>0 0 -0.002693 0 -0 0</pose>
        <mass>0.0536311</mass>
        <inertia>
          <ixx>2.877e-05</ixx>
          <ixy>0</ixy>
          <ixz>0</ixz>
          <iyy>7.083e-05</iyy>
          <iyz>-0</iyz>
          <izz>9.934e-05</izz>
        </inertia>
      </inertial>
      <collision name='leg_l_link8_collision'>
        <pose frame=''>0 0 0 0 -0 0</pose>
        <geometry>
          <mesh>
            <scale>1 1 1</scale>
            <uri>model://link08_l_toe03.stl</uri>
          </mesh>
        </geometry>
      </collision>
      <visual name='leg_l_link8_visual'>
        <pose frame=''>0 0 0 0 -0 0</pose>
        <geometry>
          <mesh>
            <scale>1 1 1</scale>
            <uri>model://link08_l_toe03.stl</uri>
          </mesh>
        </geometry>
      </visual>
    </link>
    <joint name='leg_l_joint8' type='revolute'>
      <child>leg_l_link8</child>
      <parent>leg_l_link7</parent>
      <axis>
        <xyz>0 0 1</xyz>
        <limit>
          <lower>-2.6</lower>
          <upper>2.6</upper>
          <effort>1000</effort>
          <velocity>0.5</velocity>
        </limit>
        <dynamics>
          <spring_reference>0</spring_reference>
          <spring_stiffness>0</spring_stiffness>
        </dynamics>
        <use_parent_model_frame>1</use_parent_model_frame>
      </axis>
    </joint>
    <link name='leg_l_link5'>
      <pose frame=''>0.071411 0.0175 -0.157411 3.14159 0.785393 3.14159</pose>
      <inertial>
        <pose frame=''>0.05 0.024951 -0.004912 0 -0 0</pose>
        <mass>0.0164664</mass>
        <inertia>
          <ixx>6.4e-06</ixx>
          <ixy>0</ixy>
          <ixz>0</ixz>
          <iyy>1.642e-05</iyy>
          <iyz>0</iyz>
          <izz>2.264e-05</izz>
        </inertia>
      </inertial>
      <collision name='leg_l_link5_collision'>
        <pose frame=''>0 0 0 0 -0 0</pose>
        <geometry>
          <mesh>
            <scale>1 1 1</scale>
            <uri>model://link04_l_leg02.stl</uri>
          </mesh>
        </geometry>
      </collision>
      <visual name='leg_l_link5_visual'>
        <pose frame=''>0 0 0 0 -0 0</pose>
        <geometry>
          <mesh>
            <scale>1 1 1</scale>
            <uri>model://link04_l_leg02.stl</uri>
          </mesh>
        </geometry>
      </visual>
    </link>
    <joint name='leg_l_joint5' type='revolute'>
      <child>leg_l_link5</child>
      <parent>leg_l_link3</parent>
      <axis>
        <xyz>0 -1 0</xyz>
        <limit>
          <lower>-3.14159</lower>
          <upper>3.14159</upper>
          <effort>1000</effort>
          <velocity>0.5</velocity>
        </limit>
        <dynamics>
          <spring_reference>0</spring_reference>
          <spring_stiffness>0</spring_stiffness>
        </dynamics>
        <use_parent_model_frame>1</use_parent_model_frame>
      </axis>
    </joint>
    <link name='leg_l_link6'>
      <pose frame=''>0.000699 0.0175 -0.228121 0 -0 0</pose>
      <inertial>
        <pose frame=''>-0.041661 0.024639 -0.025863 0 -0 0</pose>
        <mass>0.087992</mass>
        <inertia>
          <ixx>2.815e-05</ixx>
          <ixy>-4.1e-07</ixy>
          <ixz>9.8e-06</ixz>
          <iyy>6.846e-05</iyy>
          <iyz>-2.6e-07</iyz>
          <izz>6.529e-05</izz>
        </inertia>
      </inertial>
      <collision name='leg_l_link6_collision'>
        <pose frame=''>0 0 0 0 -0 0</pose>
        <geometry>
          <mesh>
            <scale>1 1 1</scale>
            <uri>model://link06_l_toe01.stl</uri>
          </mesh>
        </geometry>
      </collision>
      <visual name='leg_l_link6_visual'>
        <pose frame=''>0 0 0 0 -0 0</pose>
        <geometry>
          <mesh>
            <scale>1 1 1</scale>
            <uri>model://link06_l_toe01.stl</uri>
          </mesh>
        </geometry>
      </visual>
    </link>
    <joint name='leg_l_joint6_sub' type='revolute'>
      <child>leg_l_link6</child>
      <parent>leg_l_link5</parent>
      <axis>
        <xyz>0 1 0</xyz>
        <limit>
          <lower>-3.14159</lower>
          <upper>3.14159</upper>
          <effort>1000</effort>
          <velocity>0.5</velocity>
        </limit>
        <dynamics>
          <spring_reference>0</spring_reference>
          <spring_stiffness>0</spring_stiffness>
        </dynamics>
        <use_parent_model_frame>1</use_parent_model_frame>
      </axis>
    </joint>
    <link name='leg_l_link7'>
      <pose frame=''>-0.027301 0.04225 -0.267221 0 -0 0</pose>
      <inertial>
        <pose frame=''>0.026588 1e-06 -0.017825 0 -0 0</pose>
        <mass>0.1092</mass>
        <inertia>
          <ixx>3.853e-05</ixx>
          <ixy>0</ixy>
          <ixz>-4.79e-06</ixz>
          <iyy>5.192e-05</iyy>
          <iyz>0</iyz>
          <izz>3.521e-05</izz>
        </inertia>
      </inertial>
      <collision name='leg_l_link7_collision'>
        <pose frame=''>0 0 0 0 -0 0</pose>
        <geometry>
          <mesh>
            <scale>1 1 1</scale>
            <uri>model://link07_l_toe02.stl</uri>
          </mesh>
        </geometry>
      </collision>
      <visual name='leg_l_link7_visual'>
        <pose frame=''>0 0 0 0 -0 0</pose>
        <geometry>
          <mesh>
            <scale>1 1 1</scale>
            <uri>model://link07_l_toe02.stl</uri>
          </mesh>
        </geometry>
      </visual>
    </link>
    <joint name='leg_l_joint7' type='revolute'>
      <child>leg_l_link7</child>
      <parent>leg_l_link6</parent>
      <axis>
        <xyz>-1 0 0</xyz>
        <limit>
          <lower>-1.6</lower>
          <upper>1.6</upper>
          <effort>1000</effort>
          <velocity>0.5</velocity>
        </limit>
        <dynamics>
          <spring_reference>0</spring_reference>
          <spring_stiffness>0</spring_stiffness>
        </dynamics>
        <use_parent_model_frame>1</use_parent_model_frame>
      </axis>
    </joint>
    <link name='leg_l_link8'>
      <pose frame=''>0.006899 0.04225 -0.307221 0 -0 0</pose>
      <inertial>
        <pose frame=''>0 0 -0.002693 0 -0 0</pose>
        <mass>0.0536311</mass>
        <inertia>
          <ixx>2.877e-05</ixx>
          <ixy>0</ixy>
          <ixz>0</ixz>
          <iyy>7.083e-05</iyy>
          <iyz>-0</iyz>
          <izz>9.934e-05</izz>
        </inertia>
      </inertial>
      <collision name='leg_l_link8_collision'>
        <pose frame=''>0 0 0 0 -0 0</pose>
        <geometry>
          <mesh>
            <scale>1 1 1</scale>
            <uri>model://link08_l_toe03.stl</uri>
          </mesh>
        </geometry>
      </collision>
      <visual name='leg_l_link8_visual'>
        <pose frame=''>0 0 0 0 -0 0</pose>
        <geometry>
          <mesh>
            <scale>1 1 1</scale>
            <uri>model://link08_l_toe03.stl</uri>
          </mesh>
        </geometry>
      </visual>
    </link>
    <joint name='leg_l_joint8' type='revolute'>
      <child>leg_l_link8</child>
      <parent>leg_l_link7</parent>
      <axis>
        <xyz>0 0 1</xyz>
        <limit>
          <lower>-2.6</lower>
          <upper>2.6</upper>
          <effort>1000</effort>
          <velocity>0.5</velocity>
        </limit>
        <dynamics>
          <spring_reference>0</spring_reference>
          <spring_stiffness>0</spring_stiffness>
        </dynamics>
        <use_parent_model_frame>1</use_parent_model_frame>
      </axis>
    </joint>
  </model>
</sdf>
